[2025-04-10T03:08:10.345+0000] {local_task_job_runner.py:120} INFO - ::group::Pre task execution logs
[2025-04-10T03:08:10.417+0000] {taskinstance.py:2076} INFO - Dependencies all met for dep_context=non-requeueable deps ti=<TaskInstance: realtime_user_streaming_pipeline.data_validation manual__2025-04-10T03:08:08.943438+00:00 [queued]>
[2025-04-10T03:08:10.426+0000] {taskinstance.py:2076} INFO - Dependencies all met for dep_context=requeueable deps ti=<TaskInstance: realtime_user_streaming_pipeline.data_validation manual__2025-04-10T03:08:08.943438+00:00 [queued]>
[2025-04-10T03:08:10.430+0000] {taskinstance.py:2306} INFO - Starting attempt 1 of 4
[2025-04-10T03:08:10.446+0000] {taskinstance.py:2330} INFO - Executing <Task(PythonOperator): data_validation> on 2025-04-10 03:08:08.943438+00:00
[2025-04-10T03:08:10.465+0000] {standard_task_runner.py:90} INFO - Running: ['***', 'tasks', 'run', 'realtime_user_streaming_pipeline', 'data_validation', 'manual__2025-04-10T03:08:08.943438+00:00', '--job-id', '27', '--raw', '--subdir', 'DAGS_FOLDER/realtime_streaming.py', '--cfg-path', '/tmp/tmpwe8xtd1i']
[2025-04-10T03:08:10.480+0000] {standard_task_runner.py:91} INFO - Job 27: Subtask data_validation
[2025-04-10T03:08:10.483+0000] {logging_mixin.py:188} WARNING - /home/***/.local/lib/python3.12/site-packages/***/task/task_runner/standard_task_runner.py:62 DeprecationWarning: This process (pid=275) is multi-threaded, use of fork() may lead to deadlocks in the child.
[2025-04-10T03:08:10.483+0000] {standard_task_runner.py:64} INFO - Started process 278 to run task
[2025-04-10T03:08:10.602+0000] {task_command.py:426} INFO - Running <TaskInstance: realtime_user_streaming_pipeline.data_validation manual__2025-04-10T03:08:08.943438+00:00 [running]> on host 4b246fcce89d
[2025-04-10T03:08:10.753+0000] {taskinstance.py:2648} INFO - Exporting env vars: AIRFLOW_CTX_DAG_OWNER='data_engineer' AIRFLOW_CTX_DAG_ID='realtime_user_streaming_pipeline' AIRFLOW_CTX_TASK_ID='data_validation' AIRFLOW_CTX_EXECUTION_DATE='2025-04-10T03:08:08.943438+00:00' AIRFLOW_CTX_TRY_NUMBER='1' AIRFLOW_CTX_DAG_RUN_ID='manual__2025-04-10T03:08:08.943438+00:00'
[2025-04-10T03:08:10.754+0000] {taskinstance.py:430} INFO - ::endgroup::
[2025-04-10T03:08:10.783+0000] {etl_pipeline.py:94} ERROR - Error validating data: object of type 'NoneType' has no len()
[2025-04-10T03:08:10.784+0000] {taskinstance.py:441} INFO - ::group::Post task execution logs
[2025-04-10T03:08:10.784+0000] {taskinstance.py:2905} ERROR - Task failed with exception
Traceback (most recent call last):
  File "/home/airflow/.local/lib/python3.12/site-packages/airflow/models/taskinstance.py", line 465, in _execute_task
    result = _execute_callable(context=context, **execute_callable_kwargs)
             ^^^^^^^^^^^^^^^^^^^^^^^^^^^^^^^^^^^^^^^^^^^^^^^^^^^^^^^^^^^^^
  File "/home/airflow/.local/lib/python3.12/site-packages/airflow/models/taskinstance.py", line 432, in _execute_callable
    return execute_callable(context=context, **execute_callable_kwargs)
           ^^^^^^^^^^^^^^^^^^^^^^^^^^^^^^^^^^^^^^^^^^^^^^^^^^^^^^^^^^^^
  File "/home/airflow/.local/lib/python3.12/site-packages/airflow/models/baseoperator.py", line 401, in wrapper
    return func(self, *args, **kwargs)
           ^^^^^^^^^^^^^^^^^^^^^^^^^^^
  File "/home/airflow/.local/lib/python3.12/site-packages/airflow/operators/python.py", line 235, in execute
    return_value = self.execute_callable()
                   ^^^^^^^^^^^^^^^^^^^^^^^
  File "/home/airflow/.local/lib/python3.12/site-packages/airflow/operators/python.py", line 252, in execute_callable
    return self.python_callable(*self.op_args, **self.op_kwargs)
           ^^^^^^^^^^^^^^^^^^^^^^^^^^^^^^^^^^^^^^^^^^^^^^^^^^^^^
  File "/opt/airflow/pipelines/etl_pipeline.py", line 69, in validate_data
    valid_users, invalid_users, validation_summary = validate_batch(formatted_users)
                                                     ^^^^^^^^^^^^^^^^^^^^^^^^^^^^^^^
  File "/opt/airflow/pipelines/data_validator.py", line 208, in validate_batch
    "total_records": len(records),
                     ^^^^^^^^^^^^
TypeError: object of type 'NoneType' has no len()
[2025-04-10T03:08:10.795+0000] {taskinstance.py:1206} INFO - Marking task as UP_FOR_RETRY. dag_id=realtime_user_streaming_pipeline, task_id=data_validation, run_id=manual__2025-04-10T03:08:08.943438+00:00, execution_date=20250410T030808, start_date=20250410T030810, end_date=20250410T030810
[2025-04-10T03:08:10.803+0000] {standard_task_runner.py:110} ERROR - Failed to execute job 27 for task data_validation (object of type 'NoneType' has no len(); 278)
[2025-04-10T03:08:10.833+0000] {local_task_job_runner.py:243} INFO - Task exited with return code 1
[2025-04-10T03:08:10.845+0000] {taskinstance.py:3503} INFO - 0 downstream tasks scheduled from follow-on schedule check
[2025-04-10T03:08:10.845+0000] {local_task_job_runner.py:222} INFO - ::endgroup::
